2021-05-09 20:55:17,584 INFO    MainThread:6660 [internal.py:wandb_internal():88] W&B internal server running at pid: 6660, started at: 2021-05-09 20:55:17.575874
2021-05-09 20:55:17,586 INFO    WriterThread:6660 [datastore.py:open_for_write():77] open: c:\Users\Steven\Documents\Github\ML\Proyectos\Proyecto II\wandb\run-20210509_205516-vd76z3kz\run-vd76z3kz.wandb
2021-05-09 20:55:17,587 DEBUG   HandlerThread:6660 [handler.py:handle_request():121] handle_request: check_version
2021-05-09 20:55:17,597 DEBUG   SenderThread:6660 [sender.py:send():176] send: header
2021-05-09 20:55:17,597 DEBUG   SenderThread:6660 [sender.py:send_request():186] send_request: check_version
2021-05-09 20:55:20,798 DEBUG   SenderThread:6660 [sender.py:send():176] send: run
2021-05-09 20:55:24,234 INFO    SenderThread:6660 [dir_watcher.py:__init__():168] watching files in: c:\Users\Steven\Documents\Github\ML\Proyectos\Proyecto II\wandb\run-20210509_205516-vd76z3kz\files
2021-05-09 20:55:24,234 INFO    SenderThread:6660 [sender.py:_start_run_threads():696] run started: vd76z3kz with start time 1620615316
2021-05-09 20:55:24,234 DEBUG   SenderThread:6660 [sender.py:send():176] send: summary
2021-05-09 20:55:24,235 INFO    SenderThread:6660 [sender.py:_save_file():821] saving file wandb-summary.json with policy end
2021-05-09 20:55:24,237 DEBUG   HandlerThread:6660 [handler.py:handle_request():121] handle_request: run_start
2021-05-09 20:55:25,154 DEBUG   HandlerThread:6660 [meta.py:__init__():39] meta init
2021-05-09 20:55:25,154 DEBUG   HandlerThread:6660 [meta.py:__init__():53] meta init done
2021-05-09 20:55:25,155 DEBUG   HandlerThread:6660 [meta.py:probe():210] probe
2021-05-09 20:55:25,187 DEBUG   HandlerThread:6660 [meta.py:_setup_git():200] setup git
2021-05-09 20:55:25,241 INFO    Thread-12 :6660 [dir_watcher.py:_on_file_created():216] file/dir created: c:\Users\Steven\Documents\Github\ML\Proyectos\Proyecto II\wandb\run-20210509_205516-vd76z3kz\files\wandb-summary.json
2021-05-09 20:55:25,277 DEBUG   HandlerThread:6660 [meta.py:_setup_git():207] setup git done
2021-05-09 20:55:25,277 DEBUG   HandlerThread:6660 [meta.py:_save_pip():57] save pip
2021-05-09 20:55:25,278 DEBUG   HandlerThread:6660 [meta.py:_save_pip():71] save pip done
2021-05-09 20:55:25,278 DEBUG   HandlerThread:6660 [meta.py:probe():252] probe done
2021-05-09 20:55:25,348 DEBUG   SenderThread:6660 [sender.py:send():176] send: files
2021-05-09 20:55:25,348 INFO    SenderThread:6660 [sender.py:_save_file():821] saving file wandb-metadata.json with policy now
2021-05-09 20:55:25,348 DEBUG   HandlerThread:6660 [handler.py:handle_request():121] handle_request: stop_status
2021-05-09 20:55:25,350 DEBUG   SenderThread:6660 [sender.py:send_request():186] send_request: stop_status
2021-05-09 20:55:26,254 INFO    Thread-12 :6660 [dir_watcher.py:_on_file_created():216] file/dir created: c:\Users\Steven\Documents\Github\ML\Proyectos\Proyecto II\wandb\run-20210509_205516-vd76z3kz\files\output.log
2021-05-09 20:55:26,255 INFO    Thread-12 :6660 [dir_watcher.py:_on_file_created():216] file/dir created: c:\Users\Steven\Documents\Github\ML\Proyectos\Proyecto II\wandb\run-20210509_205516-vd76z3kz\files\requirements.txt
2021-05-09 20:55:26,255 INFO    Thread-12 :6660 [dir_watcher.py:_on_file_created():216] file/dir created: c:\Users\Steven\Documents\Github\ML\Proyectos\Proyecto II\wandb\run-20210509_205516-vd76z3kz\files\media\graph\graph_0_summary_6bbeb24f.graph.json
2021-05-09 20:55:26,256 INFO    Thread-12 :6660 [dir_watcher.py:_on_file_created():216] file/dir created: c:\Users\Steven\Documents\Github\ML\Proyectos\Proyecto II\wandb\run-20210509_205516-vd76z3kz\files\wandb-metadata.json
2021-05-09 20:55:26,256 INFO    Thread-12 :6660 [dir_watcher.py:_on_file_created():216] file/dir created: c:\Users\Steven\Documents\Github\ML\Proyectos\Proyecto II\wandb\run-20210509_205516-vd76z3kz\files\media
2021-05-09 20:55:26,256 INFO    Thread-12 :6660 [dir_watcher.py:_on_file_created():216] file/dir created: c:\Users\Steven\Documents\Github\ML\Proyectos\Proyecto II\wandb\run-20210509_205516-vd76z3kz\files\media\graph
2021-05-09 20:55:41,209 DEBUG   SenderThread:6660 [sender.py:send():176] send: files
2021-05-09 20:55:41,209 INFO    SenderThread:6660 [sender.py:_save_file():821] saving file media\graph\graph_0_summary_6bbeb24f.graph.json with policy now
2021-05-09 20:55:41,210 DEBUG   SenderThread:6660 [sender.py:send():176] send: summary
2021-05-09 20:55:41,212 INFO    SenderThread:6660 [sender.py:_save_file():821] saving file wandb-summary.json with policy end
2021-05-09 20:55:41,213 DEBUG   SenderThread:6660 [sender.py:send():176] send: config
2021-05-09 20:55:41,213 DEBUG   SenderThread:6660 [sender.py:send():176] send: config
2021-05-09 20:55:41,235 DEBUG   HandlerThread:6660 [handler.py:handle_request():121] handle_request: log_artifact
2021-05-09 20:55:41,235 DEBUG   SenderThread:6660 [sender.py:send_request():186] send_request: log_artifact
2021-05-09 20:55:41,407 INFO    Thread-12 :6660 [dir_watcher.py:_on_file_modified():229] file/dir modified: c:\Users\Steven\Documents\Github\ML\Proyectos\Proyecto II\wandb\run-20210509_205516-vd76z3kz\files\wandb-summary.json
2021-05-09 20:55:41,407 INFO    Thread-12 :6660 [dir_watcher.py:_on_file_created():216] file/dir created: c:\Users\Steven\Documents\Github\ML\Proyectos\Proyecto II\wandb\run-20210509_205516-vd76z3kz\files\media\table\Confusion matrix (training)_table_0_1eb51328.table.json
2021-05-09 20:55:41,408 INFO    Thread-12 :6660 [dir_watcher.py:_on_file_modified():229] file/dir modified: c:\Users\Steven\Documents\Github\ML\Proyectos\Proyecto II\wandb\run-20210509_205516-vd76z3kz\files\media
2021-05-09 20:55:41,408 INFO    Thread-12 :6660 [dir_watcher.py:_on_file_created():216] file/dir created: c:\Users\Steven\Documents\Github\ML\Proyectos\Proyecto II\wandb\run-20210509_205516-vd76z3kz\files\media\table
2021-05-09 20:55:44,366 INFO    Thread-17 :6660 [upload_job.py:push():133] Uploaded file C:\Users\Steven\AppData\Local\Temp\tmpo32hbkytwandb\2j30m98u-wandb-metadata.json
2021-05-09 20:55:44,802 INFO    Thread-18 :6660 [upload_job.py:push():133] Uploaded file C:\Users\Steven\AppData\Local\Temp\tmpo32hbkytwandb\4jkrsaiz-media/graph/graph_0_summary_6bbeb24f.graph.json
2021-05-09 20:55:48,425 INFO    Thread-20 :6660 [upload_job.py:push():91] Uploaded file C:\Users\Steven\.cache\wandb\artifacts\obj\md5\8d\8fb5eebdb40e2e4d843b354cbba932
2021-05-09 20:55:56,218 DEBUG   HandlerThread:6660 [handler.py:handle_request():121] handle_request: stop_status
2021-05-09 20:56:02,189 DEBUG   SenderThread:6660 [sender.py:send():176] send: files
2021-05-09 20:56:02,189 INFO    SenderThread:6660 [sender.py:_save_file():821] saving file media\table\Confusion matrix (training)_table_0_1eb51328.table.json with policy now
2021-05-09 20:56:02,190 DEBUG   SenderThread:6660 [sender.py:send_request():186] send_request: stop_status
2021-05-09 20:56:02,575 INFO    Thread-12 :6660 [dir_watcher.py:_on_file_modified():229] file/dir modified: c:\Users\Steven\Documents\Github\ML\Proyectos\Proyecto II\wandb\run-20210509_205516-vd76z3kz\files\config.yaml
2021-05-09 20:56:02,628 DEBUG   SenderThread:6660 [sender.py:send():176] send: stats
2021-05-09 20:56:03,067 DEBUG   HandlerThread:6660 [handler.py:handle_request():121] handle_request: log_artifact
2021-05-09 20:56:03,068 DEBUG   SenderThread:6660 [sender.py:send_request():186] send_request: log_artifact
2021-05-09 20:56:03,300 INFO    Thread-21 :6660 [upload_job.py:push():133] Uploaded file C:\Users\Steven\AppData\Local\Temp\tmpo32hbkytwandb\24kljeqx-media/table/Confusion matrix (training)_table_0_1eb51328.table.json
2021-05-09 20:56:03,582 INFO    Thread-12 :6660 [dir_watcher.py:_on_file_created():216] file/dir created: c:\Users\Steven\Documents\Github\ML\Proyectos\Proyecto II\wandb\run-20210509_205516-vd76z3kz\files\media\table\Confusion matrix (testing)_table_0_f51d42c9.table.json
2021-05-09 20:56:03,583 INFO    Thread-12 :6660 [dir_watcher.py:_on_file_modified():229] file/dir modified: c:\Users\Steven\Documents\Github\ML\Proyectos\Proyecto II\wandb\run-20210509_205516-vd76z3kz\files\media\table
2021-05-09 20:56:06,807 INFO    Thread-23 :6660 [upload_job.py:push():91] Uploaded file C:\Users\Steven\.cache\wandb\artifacts\obj\md5\cd\0233e73f900c14092e0b00b417be7b
2021-05-09 20:56:17,642 DEBUG   HandlerThread:6660 [handler.py:handle_request():121] handle_request: stop_status
2021-05-09 20:56:56,233 WARNING FileStreamThread:6660 [file_stream.py:request_with_retry():419] requests_with_retry encountered retryable exception: ('Connection aborted.', TimeoutError(10060, 'Se produjo un error durante el intento de conexión ya que la parte conectada no respondió adecuadamente tras un periodo de tiempo, o bien se produjo un error en la conexión establecida ya que el host conectado no ha podido responder', None, 10060, None)). func: <bound method Session.post of <requests.sessions.Session object at 0x000001BB795AE610>>, args: ('https://api.wandb.ai/files/tecai/MLP/vd76z3kz/file_stream',), kwargs: {'json': {'complete': False, 'failed': False}}
2021-05-09 20:57:03,490 WARNING MainThread:6660 [internal.py:is_dead():366] Internal process exiting, parent pid 3056 disappeared
2021-05-09 20:57:03,490 ERROR   MainThread:6660 [internal.py:wandb_internal():143] Internal process shutdown.
2021-05-09 20:57:04,073 INFO    WriterThread:6660 [datastore.py:close():258] close: c:\Users\Steven\Documents\Github\ML\Proyectos\Proyecto II\wandb\run-20210509_205516-vd76z3kz\run-vd76z3kz.wandb
2021-05-09 20:57:04,074 INFO    HandlerThread:6660 [handler.py:finish():632] shutting down handler
2021-05-09 20:57:06,307 ERROR   Thread-11 :6660 [retry.py:__call__():126] Retry attempt failed:
Traceback (most recent call last):
  File "C:\Python39\lib\site-packages\urllib3\connectionpool.py", line 382, in _make_request
    self._validate_conn(conn)
  File "C:\Python39\lib\site-packages\urllib3\connectionpool.py", line 1010, in _validate_conn
    conn.connect()
  File "C:\Python39\lib\site-packages\urllib3\connection.py", line 411, in connect
    self.sock = ssl_wrap_socket(
  File "C:\Python39\lib\site-packages\urllib3\util\ssl_.py", line 428, in ssl_wrap_socket
    ssl_sock = _ssl_wrap_socket_impl(
  File "C:\Python39\lib\site-packages\urllib3\util\ssl_.py", line 472, in _ssl_wrap_socket_impl
    return ssl_context.wrap_socket(sock, server_hostname=server_hostname)
  File "C:\Python39\lib\ssl.py", line 500, in wrap_socket
    return self.sslsocket_class._create(
  File "C:\Python39\lib\ssl.py", line 1040, in _create
    self.do_handshake()
  File "C:\Python39\lib\ssl.py", line 1309, in do_handshake
    self._sslobj.do_handshake()
socket.timeout: _ssl.c:1105: The handshake operation timed out

During handling of the above exception, another exception occurred:

Traceback (most recent call last):
  File "C:\Python39\lib\site-packages\requests\adapters.py", line 439, in send
    resp = conn.urlopen(
  File "C:\Python39\lib\site-packages\urllib3\connectionpool.py", line 755, in urlopen
    retries = retries.increment(
  File "C:\Python39\lib\site-packages\urllib3\util\retry.py", line 532, in increment
    raise six.reraise(type(error), error, _stacktrace)
  File "C:\Python39\lib\site-packages\urllib3\packages\six.py", line 735, in reraise
    raise value
  File "C:\Python39\lib\site-packages\urllib3\connectionpool.py", line 699, in urlopen
    httplib_response = self._make_request(
  File "C:\Python39\lib\site-packages\urllib3\connectionpool.py", line 385, in _make_request
    self._raise_timeout(err=e, url=url, timeout_value=conn.timeout)
  File "C:\Python39\lib\site-packages\urllib3\connectionpool.py", line 336, in _raise_timeout
    raise ReadTimeoutError(
urllib3.exceptions.ReadTimeoutError: HTTPSConnectionPool(host='api.wandb.ai', port=443): Read timed out. (read timeout=10)

During handling of the above exception, another exception occurred:

Traceback (most recent call last):
  File "C:\Python39\lib\site-packages\wandb\sdk\lib\retry.py", line 102, in __call__
    result = self._call_fn(*args, **kwargs)
  File "C:\Python39\lib\site-packages\wandb\sdk\internal\internal_api.py", line 127, in execute
    return self.client.execute(*args, **kwargs)
  File "C:\Python39\lib\site-packages\wandb\vendor\gql-0.2.0\gql\client.py", line 52, in execute
    result = self._get_result(document, *args, **kwargs)
  File "C:\Python39\lib\site-packages\wandb\vendor\gql-0.2.0\gql\client.py", line 60, in _get_result
    return self.transport.execute(document, *args, **kwargs)
  File "C:\Python39\lib\site-packages\wandb\vendor\gql-0.2.0\gql\transport\requests.py", line 38, in execute
    request = requests.post(self.url, **post_args)
  File "C:\Python39\lib\site-packages\requests\api.py", line 119, in post
    return request('post', url, data=data, json=json, **kwargs)
  File "C:\Python39\lib\site-packages\requests\api.py", line 61, in request
    return session.request(method=method, url=url, **kwargs)
  File "C:\Python39\lib\site-packages\requests\sessions.py", line 542, in request
    resp = self.send(prep, **send_kwargs)
  File "C:\Python39\lib\site-packages\requests\sessions.py", line 655, in send
    r = adapter.send(request, **kwargs)
  File "C:\Python39\lib\site-packages\requests\adapters.py", line 529, in send
    raise ReadTimeout(e, request=request)
requests.exceptions.ReadTimeout: HTTPSConnectionPool(host='api.wandb.ai', port=443): Read timed out. (read timeout=10)
2021-05-09 20:57:10,287 WARNING FileStreamThread:6660 [file_stream.py:request_with_retry():419] requests_with_retry encountered retryable exception: HTTPSConnectionPool(host='api.wandb.ai', port=443): Max retries exceeded with url: /files/tecai/MLP/vd76z3kz/file_stream (Caused by SSLError(SSLEOFError(8, 'EOF occurred in violation of protocol (_ssl.c:1122)'))). func: <bound method Session.post of <requests.sessions.Session object at 0x000001BB795AE610>>, args: ('https://api.wandb.ai/files/tecai/MLP/vd76z3kz/file_stream',), kwargs: {'json': {'complete': False, 'failed': False}}
2021-05-09 20:57:25,617 WARNING FileStreamThread:6660 [file_stream.py:request_with_retry():419] requests_with_retry encountered retryable exception: HTTPSConnectionPool(host='api.wandb.ai', port=443): Max retries exceeded with url: /files/tecai/MLP/vd76z3kz/file_stream (Caused by SSLError(SSLEOFError(8, 'EOF occurred in violation of protocol (_ssl.c:1122)'))). func: <bound method Session.post of <requests.sessions.Session object at 0x000001BB795AE610>>, args: ('https://api.wandb.ai/files/tecai/MLP/vd76z3kz/file_stream',), kwargs: {'json': {'complete': False, 'failed': False}}
2021-05-09 20:57:56,644 WARNING FileStreamThread:6660 [file_stream.py:request_with_retry():419] requests_with_retry encountered retryable exception: HTTPSConnectionPool(host='api.wandb.ai', port=443): Max retries exceeded with url: /files/tecai/MLP/vd76z3kz/file_stream (Caused by NewConnectionError('<urllib3.connection.HTTPSConnection object at 0x000001BB795E6A30>: Failed to establish a new connection: [WinError 10060] Se produjo un error durante el intento de conexión ya que la parte conectada no respondió adecuadamente tras un periodo de tiempo, o bien se produjo un error en la conexión establecida ya que el host conectado no ha podido responder')). func: <bound method Session.post of <requests.sessions.Session object at 0x000001BB795AE610>>, args: ('https://api.wandb.ai/files/tecai/MLP/vd76z3kz/file_stream',), kwargs: {'json': {'complete': False, 'failed': False}}
2021-05-09 20:58:24,577 WARNING FileStreamThread:6660 [file_stream.py:request_with_retry():419] requests_with_retry encountered retryable exception: HTTPSConnectionPool(host='api.wandb.ai', port=443): Max retries exceeded with url: /files/tecai/MLP/vd76z3kz/file_stream (Caused by NewConnectionError('<urllib3.connection.HTTPSConnection object at 0x000001BB7A6D64C0>: Failed to establish a new connection: [Errno 11001] getaddrinfo failed')). func: <bound method Session.post of <requests.sessions.Session object at 0x000001BB795AE610>>, args: ('https://api.wandb.ai/files/tecai/MLP/vd76z3kz/file_stream',), kwargs: {'json': {'complete': False, 'failed': False}}
2021-05-09 20:59:17,321 WARNING FileStreamThread:6660 [file_stream.py:request_with_retry():419] requests_with_retry encountered retryable exception: ('Connection aborted.', RemoteDisconnected('Remote end closed connection without response')). func: <bound method Session.post of <requests.sessions.Session object at 0x000001BB795AE610>>, args: ('https://api.wandb.ai/files/tecai/MLP/vd76z3kz/file_stream',), kwargs: {'json': {'complete': False, 'failed': False}}
2021-05-09 21:01:28,426 WARNING FileStreamThread:6660 [file_stream.py:request_with_retry():419] requests_with_retry encountered retryable exception: ('Connection aborted.', TimeoutError(10060, 'Se produjo un error durante el intento de conexión ya que la parte conectada no respondió adecuadamente tras un periodo de tiempo, o bien se produjo un error en la conexión establecida ya que el host conectado no ha podido responder', None, 10060, None)). func: <bound method Session.post of <requests.sessions.Session object at 0x000001BB795AE610>>, args: ('https://api.wandb.ai/files/tecai/MLP/vd76z3kz/file_stream',), kwargs: {'json': {'complete': False, 'failed': False}}
2021-05-09 21:09:14,967 WARNING FileStreamThread:6660 [file_stream.py:request_with_retry():419] requests_with_retry encountered retryable exception: ('Connection aborted.', TimeoutError(10060, 'Se produjo un error durante el intento de conexión ya que la parte conectada no respondió adecuadamente tras un periodo de tiempo, o bien se produjo un error en la conexión establecida ya que el host conectado no ha podido responder', None, 10060, None)). func: <bound method Session.post of <requests.sessions.Session object at 0x000001BB795AE610>>, args: ('https://api.wandb.ai/files/tecai/MLP/vd76z3kz/file_stream',), kwargs: {'json': {'complete': False, 'failed': False}}
2021-05-09 21:09:28,690 WARNING FileStreamThread:6660 [file_stream.py:request_with_retry():419] requests_with_retry encountered retryable exception: HTTPSConnectionPool(host='api.wandb.ai', port=443): Max retries exceeded with url: /files/tecai/MLP/vd76z3kz/file_stream (Caused by NewConnectionError('<urllib3.connection.HTTPSConnection object at 0x000001BB795D1C40>: Failed to establish a new connection: [Errno 11001] getaddrinfo failed')). func: <bound method Session.post of <requests.sessions.Session object at 0x000001BB795AE610>>, args: ('https://api.wandb.ai/files/tecai/MLP/vd76z3kz/file_stream',), kwargs: {'json': {'complete': False, 'failed': False}}
2021-05-09 21:09:44,207 WARNING FileStreamThread:6660 [file_stream.py:request_with_retry():419] requests_with_retry encountered retryable exception: HTTPSConnectionPool(host='api.wandb.ai', port=443): Max retries exceeded with url: /files/tecai/MLP/vd76z3kz/file_stream (Caused by NewConnectionError('<urllib3.connection.HTTPSConnection object at 0x000001BB795D1CA0>: Failed to establish a new connection: [Errno 11001] getaddrinfo failed')). func: <bound method Session.post of <requests.sessions.Session object at 0x000001BB795AE610>>, args: ('https://api.wandb.ai/files/tecai/MLP/vd76z3kz/file_stream',), kwargs: {'json': {'complete': False, 'failed': False}}
2021-05-09 21:10:03,967 WARNING FileStreamThread:6660 [file_stream.py:request_with_retry():419] requests_with_retry encountered retryable exception: HTTPSConnectionPool(host='api.wandb.ai', port=443): Max retries exceeded with url: /files/tecai/MLP/vd76z3kz/file_stream (Caused by NewConnectionError('<urllib3.connection.HTTPSConnection object at 0x000001BB795D19D0>: Failed to establish a new connection: [Errno 11001] getaddrinfo failed')). func: <bound method Session.post of <requests.sessions.Session object at 0x000001BB795AE610>>, args: ('https://api.wandb.ai/files/tecai/MLP/vd76z3kz/file_stream',), kwargs: {'json': {'complete': False, 'failed': False}}
2021-05-09 21:10:23,144 WARNING FileStreamThread:6660 [file_stream.py:request_with_retry():419] requests_with_retry encountered retryable exception: HTTPSConnectionPool(host='api.wandb.ai', port=443): Max retries exceeded with url: /files/tecai/MLP/vd76z3kz/file_stream (Caused by NewConnectionError('<urllib3.connection.HTTPSConnection object at 0x000001BB795D1F10>: Failed to establish a new connection: [Errno 11001] getaddrinfo failed')). func: <bound method Session.post of <requests.sessions.Session object at 0x000001BB795AE610>>, args: ('https://api.wandb.ai/files/tecai/MLP/vd76z3kz/file_stream',), kwargs: {'json': {'complete': False, 'failed': False}}
